<?xml version="1.0" ?>
<!-- =================================================================================== -->
<!-- |    This document was autogenerated by xacro from robot.urdf.xacro               | -->
<!-- |    EDITING THIS FILE BY HAND IS NOT RECOMMENDED                                 | -->
<!-- =================================================================================== -->
<robot name="robot">
  <!-- Specify some standard inertial calculations https://en.wikipedia.org/wiki/List_of_moments_of_inertia -->
  <!-- These make use of xacro's mathematical functionality -->
  <material name="white">
    <color rgba="1 1 1 1"/>
  </material>
  <material name="orange">
    <color rgba="1 0.3 0.1 1"/>
  </material>
  <material name="blue">
    <color rgba="0.2 0.2 1 1"/>
  </material>
  <material name="black">
    <color rgba="0 0 0 1"/>
  </material>
  <!-- BASE LINK -->
  <link name="base_link">

    </link>
  <!-- CHASSIS LINK -->
  <joint name="chassis_joint" type="fixed">
    <parent link="base_link"/>
    <child link="chassis"/>
    <origin xyz = "0 0 0"/>
  </joint>
  <link name="chassis">
    <visual>
      <!-- <origin xyz="0.15 0 0.075"/> -->
      <geometry>
        <!-- import file stl มีหน่วยเป็นเมตร ขนาดคือส่วนที่กำหนดมาแล้วจาก STL โดยที่ปรับคือการปรับ scale xyz `-->
        <mesh filename="package://mobile-0244/stl/assbodynew.STL" scale = "0.001 0.001 0.001 "/>
        <!-- <box size="0.3 0.3 0.15"/> -->
      </geometry>
      <!-- y x z -->
      <origin xyz = "-0.1 -0.105 -0.07 " rpy = "1.56 0 1.56" />
      <material name="white"/>
    </visual>
    <collision>
      <!-- <origin xyz="0.15 0 0.075"/> -->
      <geometry>
        <!-- import file stl มีหน่วยเป็นเมตร ขนาดคือส่วนที่กำหนดมาแล้วจาก STL โดยที่ปรับคือการปรับ scale xyz `-->
        <mesh filename="package://mobile-0244/stl/assbodynew.STL" scale = "0.001 0.001 0.001 "/>
        <!-- <box size="0.3 0.3 0.15"/> -->
      </geometry>
      <origin xyz = "-0.1 -0.105 -0.07 " rpy = "1.56 0 1.56" />

    </collision>
    <inertial>
      <origin xyz = "0 0 0" rpy = "1.56 0 1.56" />
      <mass value="0.5"/>
      <inertia ixx="0.004687499999999999" ixy="0.0" ixz="0.0" iyy="0.004687499999999999" iyz="0.0" izz="0.0075"/>
    </inertial>
  </link>
  <!-- LEFT WHEEL LINK -->
  <joint name="left_wheel" type="continuous">
    <parent link="base_link"/>
    <child link="left_wheel_link"/>
    <!-- <origin rpy="-1.5707963267948966 0 0" xyz="0 0.175 0"/> -->
    <origin xyz = "0.043 0.085 0.034"/>
    <axis xyz="0 0 1"/>
    <dynamics damping="0.5" friction="100.0"/>
  </joint>
  <link name="left_wheel_link">
    <visual>
      <geometry>
      <!-- import file stl มีหน่วยเป็นเมตร ขนาดคือส่วนที่กำหนดมาแล้วจาก STL โดยที่ปรับคือการปรับ scale xyz `-->
        <mesh filename="package://mobile-0244/stl/well.STL" scale = "0.001 0.001 0.001 "/>
        <!-- <cylinder length="0.04" radius="0.05"/> -->
      </geometry>
      <origin xyz = "0.033 0 -0.034" rpy = "1.56 0 3.12" />

      <material name="blue"/>
    </visual>
    <collision>
      <geometry>
      <!-- import file stl มีหน่วยเป็นเมตร ขนาดคือส่วนที่กำหนดมาแล้วจาก STL โดยที่ปรับคือการปรับ scale xyz `-->
        <mesh filename="package://mobile-0244/stl/well.STL" scale = "0.001 0.001 0.001 "/>
        <!-- <cylinder length="0.04" radius="0.05"/> -->
      </geometry>
      <origin xyz = "0.033 0 -0.034" rpy = "1.56 0 0" />

    </collision>
    <inertial>
      <origin xyz = "0 0 0" rpy = "1.56 0 0" />
      <mass value="0.1"/>
      <inertia ixx="7.583333333333335e-05" ixy="0.0" ixz="0.0" iyy="7.583333333333335e-05" iyz="0.0" izz="0.00012500000000000003"/>
    </inertial>
  </link>
  <transmission name="left_wheel_trans" type="SimpleTransmission">
    <type>transmission_interface/SimpleTransmission</type>
    <actuator name="left_wheel_motor">
      <mechanicalReduction>1</mechanicalReduction>
    </actuator>
    <joint name="left_wheel">
      <hardwareInterface>hardware_interface/VelocityJointInterface</hardwareInterface>
    </joint>
  </transmission>
  <!-- RIGHT WHEEL LINK -->
  <joint name="right_wheel" type="continuous">
    <parent link="base_link"/>
    <child link="right_wheel_link"/>
    <origin xyz = "0.04 -0.09 0.034"/>
    <axis xyz="0 0 -1"/>
    <dynamics damping="0.5" friction="100.0"/>
  </joint>
  <link name="right_wheel_link">
    <visual>
      <geometry>
      <!-- import file stl มีหน่วยเป็นเมตร ขนาดคือส่วนที่กำหนดมาแล้วจาก STL โดยที่ปรับคือการปรับ scale xyz `-->
        <mesh filename="package://mobile-0244/stl/well.STL" scale = "0.001 0.001 0.001 "/>
        <!-- <cylinder length="0.04" radius="0.05"/> -->
      </geometry>
      <!-- <origin xyz = "0.01 -0.09 0" rpy = "1.56 0 0" /> -->
      <origin xyz = "-0.033 0 -0.034" rpy = "1.56 0 0" />
      <material name="blue"/>
    </visual>
    <collision>
      <geometry>
      <!-- import file stl มีหน่วยเป็นเมตร ขนาดคือส่วนที่กำหนดมาแล้วจาก STL โดยที่ปรับคือการปรับ scale xyz `-->
        <mesh filename="package://mobile-0244/stl/well.STL" scale = "0.001 0.001 0.001 "/>
        <!-- <cylinder length="0.04" radius="0.05"/> -->
      </geometry>
      <origin xyz = "-0.033 0 -0.034" rpy = "1.56 0 0" />
      
    </collision>
    <inertial>
      <origin xyz = "0 0 0" rpy = "1.56 0 0" />
      <mass value="0.1"/>
      <inertia ixx="7.583333333333335e-05" ixy="0.0" ixz="0.0" iyy="7.583333333333335e-05" iyz="0.0" izz="0.00012500000000000003"/>
    </inertial>
  </link>
  <transmission name="right_wheel_trans" type="SimpleTransmission">
    <type>transmission_interface/SimpleTransmission</type>
    <actuator name="right_wheel_motor">
      <mechanicalReduction>1</mechanicalReduction>
    </actuator>
    <joint name="right_wheel">
      <hardwareInterface>hardware_interface/VelocityJointInterface</hardwareInterface>
    </joint>
  </transmission>
  <!--Front CASTER WHEEL LINK -->
  <!-- <joint name="caster_wheel_joint" type="fixed">
        <parent link="chassis"/>
        <child link="caster_wheel"/>
        <origin xyz="0.24 0 0"/>
        <dynamics damping="0.0" friction="0.0" />
    </joint> -->
  <joint name="caster_wheel_joint" type="continuous"> -->
    <parent link="chassis"/>
    <child link="caster_wheel"/>
    <origin xyz="-0.03 0 0"/>
    <axis xyz="0 1 0"/>
    <!-- Axis of rotation perpendicular to the wheel -->
    <dynamics damping="0.0" friction="0.0"/>
  </joint>
  <link name="caster_wheel">
    <visual>
      <geometry>
        <sphere radius="0.015"/>
      </geometry>
      <material name="black"/>
    </visual>
    <collision>
      <geometry>
        <sphere radius="0.015"/>
      </geometry>
      <surface>
        <friction>
          <ode>
            <mu>0.0</mu>
            <!-- Set friction to zero -->
            <mu2>0.0</mu2>
            Set friction to zero
          </ode>
        </friction>
      </surface>
    </collision>
    <inertial>
      <origin rpy="0 0 0" xyz="0 0 0"/>
      <mass value="0.1"/>
      <inertia ixx="0.00010000000000000005" ixy="0.0" ixz="0.0" iyy="0.00010000000000000005" iyz="0.0" izz="0.00010000000000000005"/>
    </inertial>
  </link>

      <!-- Add a Sensor Link -->
  <link name="lidar_link">
      <visual>
        <!-- Visual properties of the lidar sensor -->
        <geometry>
            <cylinder radius="0.03" length="0.03" /> <!-- Example shape, adjust as needed -->
        </geometry>
          <material name="blue" /> <!-- Example material, adjust as needed -->
      </visual>
      <collision>
        <!-- Collision properties of the lidar sensor -->
        <geometry>
            <cylinder radius="0.03" length="0.06" /> <!-- Example shape, adjust as needed -->
        </geometry>
      </collision>
        <!-- Define inertial properties if necessary -->
  </link>

    <!-- Attach the Sensor to the Robot -->
  <joint name="lidar_joint" type="fixed">
    <parent link="chassis"/>
    <child link="lidar_link"/>
    <origin xyz="0 0 0.15" rpy="0 0 0"/>
  </joint>

  <gazebo reference="lidar_link">
    <material>Gazebo/Red</material>
 
      <sensor name="lidar" type="ray">
        <pose> 0 0 0 0 0 0 </pose>
        <visualize>true</visualize>
        <update_rate>10</update_rate>
        <ray>
          <scan>
              <horizontal>
                <samples>360</samples>
                <min_angle>-3.14</min_angle>
                <max_angle>3.14</max_angle>
              </horizontal>
          </scan>
          <range>
            <min>0.3</min>
            <max>12</max>
          </range>
        </ray>
            <!-- <plugin name="laser_controller" filename="libgazebo_ros_ray_sensor.so">
                <ros>
                    <argument>~/out:=scan</argument>
                </ros>
                <output_type>sensor_msgs/LaserScan</output_type>
                <frame_name>lidar_link</frame_name>
            </plugin> -->
        <plugin name="lidar_controller" filename="libgazebo_ros_laser.so">
          <topicName>/scan</topicName>
          <frameName>lidar_link</frameName>
        </plugin>

      </sensor>
  </gazebo>
    

  <gazebo>
    <plugin filename="libgazebo_ros_control.so" name="gazebo_ros_control">
      <robotNamespace>/</robotNamespace>
      <legacyModeNS>true</legacyModeNS>
    </plugin>
  </gazebo>
  <!-- use component -->
</robot>
